Workbook

Sheet ACTIVOS
AR1: Código: F-DM-45
AR2: Versión: 02 | AT2: Pág.: 1 de 1
AR3: Fecha emisión: 1/03/2017
AR4: Última revisión: 25/05/2024
B6: FECHA DE ACTUALIZACION | C6: 46099
V7: RUNT POR PLACA Y CEDULA DE PROPIETARIO | AG7: RUNT POR CEDULA | AN7: SIMIT
T8: PROPIETARIO ACTUAL | AC8: RTM | AE8: SOAT | AG8: LICENCIA DE CONDUCCIÓN | AN8: INFRACCIONES | AU8: VALIDACIÓN RETIRO
B9: CEDULA | C9: NOMBRE | D9: ESTADO ACTUAL (La fecha es el dia del retiro) | E9: FECHA DE INGRESO | F9: FECHA DE NACIMIENTO | G9: EDAD | H9: GÉNERO | I9: ESTADO CIVIL | J9: ESCOLARIDAD | K9: CORREO CORPORATIVO | L9: CARGO | M9: AREA | N9: DEPARTAMENTO | O9: ES CONDUCTOR LABORAL | P9: RODAMIENTO | Q9: TIPO | R9: PLACA | S9: ¿ES PROPIETARIO? | T9: NOMBRE | U9: IDENTIFICACIÓN | V9: NUMERO VIN | W9: NUMERO MOTOR | X9: MODELO | Y9: MARCA | Z9: CILINDRAJE | AA9: KILOMETRAJE | AB9: FECHA DE MATRICULA | AC9: ESTADO ACTUAL | AD9: FECHA VENCIMIENTO | AE9: ESTADO ACTUAL | AF9: FECHA VENCIMIENTO | AG9: CATEGORIA DE LICENCIA PARA LA LABOR | AH9: CATEGORIA ACTUAL | AI9: FECHA VENCIMIENTO DE LICENCIA PARA LA LABOR | AJ9: ESTADO ACTUAL | AK9: RESTRICCIONES | AL9: CUMPLIMIENTO (3 CUMPLE TOTALMENTE) | AM9: REPORTE DE SINIESTROS VIALES | AN9: CODIGO | AO9: DESCRIPCION | AP9: FECHA | AQ9: ESTADO | AR9: ESTADO DE PAGO | AS9: FECHA DE REVISION DEL SIMIT Y RUNT POR CC Y PLCA | AT9: OBSERVACIONES

Sheet EGRESOS
A1: CEDULA | B1: NOMBRE INTEGRANTE | C1: FECHA DE RETIRO
A2: 1151941400 | B2: ESPINOSA PANCHO CARMENZA | C2: 45381
A3: 1089514916 | B3: CABEZAS TENORIO JERSON DANIEL | C3: 45383
A4: 14638890 | B4: GARCIA LIMA CESAR FELIPE | C4: 45383
A5: 1130660013 | B5: LOPEZ ZAPATA VANESSA | C5: 45383
A6: 1112480811 | B6: RAMOS HOYOS MIGUEL ESNEIDER | C6: 45383
A7: 1002620679 | B7: DIAZ SALAZAR LUISA MARIA | C7: 45386
A8: 1112491890 | B8: MARULANDA PERDIGON DIEGO ALEJANDRO | C8: 45386
A9: 1151960974 | B9: MARTINEZ CASTILLO LINA VANESA | C9: 45387
A10: 1113653077 | B10: NARANJO MONTALVO JOHN JAIRO | C10: 45388
A11: 1144139543 | B11: ORREGO HERNANDEZ MARIA ELSURY | C11: 45388
A12: 1144076253 | B12: ZUNIGA HOLGUIN CHRISTIAN EFREN | C12: 45388
A13: 31574426 | B13: GONZALEZ MURIEL IVETTE CATHERINE | C13: 45389
... A28: 1143964853 | B28: GALLEGO PALMA CAROLINA | C28: 45407
A29: #VALUE! | B29: GIRALDO RICAURTE GLORIA STEPHANY | C29: 45407
A30: #VALUE! | B30: HOLGUIN RESPTREPO DIANA PATRICIA | C30: 45407
A31: 1125251112 | B31: LENIS OBANDO LEIDY MARCELA | C31: 45407
A32: 1112221668 | B32: QUIÑONES PARRA PAOLA ANDREA | C32: 45407
A33: 1005874043 | B33: TASCON BASTIDAS JESSICA | C33: 45407
A34: 1006166997 | B34: NICOLE HENAO STACEY | C34: 45408
A35: 1060879942 | B35: MONTENEGRO IBARRA ANGELICA | C35: 45408
A36: #VALUE! | B36: AGUIRRE ORTIZ HOFMMAN RODOLFO | C36: 45412
A37: 67043152 | B37: CABRERA GUEGIA ANA MIREYA | C37: 45412
A38: 1151954224 | B38: CASTRO MONTEZUMA DANIEL ANDRES | C38: 45412
A39: #VALUE! | B39: JIMENEZ GARCIA YAMILETH | C39: 45412
A40: 1007850898 | B40: MONTANO BONILLA NAIROBY | C40: 45412
A41: 66781921 | B41: PEREZ MARTINEZ ERICA MARIA | C41: 45412
A42: 38671318 | B42: SANCHEZ LEON MYRIAM | C42: 45412
A43: 1130621193 | B43: VELASQUEZ SERNA CHRISTIAN | C43: 45413
A44: 1144149748 | B44: LUCUMI LOPEZ FABER ALBERTO | C44: 45413
A45: 1007850898 | B45: MONTANO BONILLA NAIROBY | C45: 45413
A46: 1144075120 | B46: LEMOS FLOREZ JENNIFER | C46: 45415
A47: 1087111419 | B47: RINCON ANGULO JAIME IVAN | C47: 45415
A48: 1143859721 | B48: ROSERO MINA LINA MARCELA | C48: 45418
A49: 1006295430 | B49: LOPEZ DUQUE DAISY JOHANA | C49: 45418
A50: 1143990472 | B50: AGUIRRE CORREA WILLIAM | C50: 45419
A51: 14635479 | B51: CALDERON SOTO DIEGO ALEJANDRO | C51: 45427
... A351: 1107074876 | B351: Sebastian Ospina Figueroa | C351: 45769
A352: #VALUE! | B352: Darly Yurani Hinestroza Mosquera | C352: 45769
A353: 1006235611 | B353: LEMUS CASTANEDA JHOAN SEBASTIAN | C353: 45769
...

Sheet LISTADO DE INFRACCIONES
A1: NUMERO DE INFRACCIONES INTEGRANTES REDCOLSA | B1: CÓDIGO | C1: DESCRIPCIÓN INFRACCIÓN | D1: MULTA / 2026 | E1: 50% Día 1°Hasta Día 5° Hábil | F1: 75% Día 6° HastaDía 20 Hábil
A2: =COUNTIF(ACTIVOS!AN10:$AN$768,B2) -> 0 | B2: A01 | C2: No transitar por la derecha de la via. | D2: 168900 | E2: 84450 | F2: 126675 | G2: INFRACCIÓN PARA CONDUCTORES DE VEHÍCULO NO AUTOMOTOR O DE TRACCIÓN ANIMAL | I2: COMPARENDO | J2: ACUERDO DE PAGO
A3: =COUNTIF(ACTIVOS!AN11:$AN$768,B3) -> 0 | B3: A02 | C3: Agarrarse de otro vehículo en circulación. | D3: 168900 | E3: 84450 | F3: 126675 | I3: MULTA | J3: SIN ACUERDO DE PAGO
A4: =COUNTIF(ACTIVOS!AN12:$AN$768,B4) -> 0 | B4: A03 | C4: Transportar personas o cosas que disminuyan su visibilidad e incomoden la conducción. | D4: 168900 | E4: 84450 | F4: 126675 | J4: CANCELADO
A5: =COUNTIF(ACTIVOS!AN13:$AN$768,B5) -> 0 | B5: A04 | C5: Transitar por andenes y demás lugares destinados al tránsito de peatones. | D5: 168900 | E5: 84450 | F5: 126675
A6: =COUNTIF(ACTIVOS!AN14:$AN$768,B6) -> 0 | B6: A05 | C6: No respetar las señales de tránsito. | D6: 168900 | E6: 84450 | F6: 126675
A7: =COUNTIF(ACTIVOS!AN15:$AN$768,B7) -> 0 | B7: A06 | C7: Transitar sin los dispositivos luminosos requeridos. | D7: 168900 | E7: 84450 | F7: 126675
A8: =COUNTIF(ACTIVOS!AN16:$AN$768,B8) -> 0 | B8: A07 | C8: Transitar sin dispositivos que permitan la parada inmediata o con ellos, pero en estado defectuoso. | D8: 168900 | E8: 84450 | F8: 126675
A9: =COUNTIF(ACTIVOS!AN17:$AN$768,B9) -> 0 | B9: A08 | C9: Transitar por zonas prohibidas o, por aquellas vías en donde las autoridades competentes lo prohíban o, conducir por vías diferentes a aquellas especialmente diseñadas para ello cuando las hubiere | D9: 168900 | E9: 84450 | F9: 126675
A10: =COUNTIF(ACTIVOS!AN18:$AN$768,B10) -> 0 | B10: A09 | C10: Adelantar entre dos (2) vehículos automotores que estén en sus respectivos carriles. | D10: 168900 | E10: 84450 | F10: 126675
A11: =COUNTIF(ACTIVOS!AN19:$AN$768,B11) -> 0 | B11: A10 | C11: Conducir por la vía férrea o por zonas de protección y seguridad. | D11: 168900 | E11: 84450 | F11: 126675
A12: =COUNTIF(ACTIVOS!AN20:$AN$768,B12) -> 0 | B12: A11 | C12: Transitar por zonas restringidas o por vías de alta velocidad como autopistas y arterias, en este caso el vehículo no automotor será inmovilizado. | D12: 168900 | E12: 84450 | F12: 126675
A13: =COUNTIF(ACTIVOS!AN21:$AN$768,B13) -> 0 | B13: A12 | C13: Prestar servicio público con este tipo de vehículos. Además, el vehículo será inmovilizado por primera vez, por el término de cinco días, por segunda vez veinte dias y por tercera vez cuarenta dias. | D13: 168900 | E13: 84450 | F13: 126675
A14: =COUNTIF(ACTIVOS!AN22:$AN$768,B14) -> 0 | B14: B01 | C14: Conducir un vehículo sin llevar consigo la licencia de conducción. | D14: 337400 | E14: 168700 | F14: 253050 | G14: CONDUCTOR DE UN VEHÍCULO AUTOMOTOR
A15: =COUNTIF(ACTIVOS!AN23:$AN$768,B15) -> 0 | B15: B02 | C15: Conducir un vehículo con la licencia de conducción vencida, de acuerdo a los siguientes casos: a) El conductor de servicio público que no refrende su licencia de conducción cada tres (3) años; b) El conductor de servicio público mayor de sesenta años (60) que no refrende su licencia de conducción anualmente; c) El conductor de servicio diferente al público que a partir de los sesenta y cinco (65) años de edad, no refrende su licencia de conducción cada tres (3) años; d) El conductor de servicio diferente al público, que no refrende su licencia de conducción cada cinco (5) años. INMOVILIZACIÓN: SI | D15: 337400 | E15: 168700 | F15: 253050
A16: =COUNTIF(ACTIVOS!AN24:$AN$768,B16) -> 0 | B16: B03 | C16: Conducir un vehículo sin placas, no portarlas en el extremo delantero o trasero, portarlas con obstáculos o en condiciones que dificulten su plena identificación, portar en el lugar destinado a las placas, distintivos similares a estas o que la imiten, o que correspondan a placas de otros países o, sin el permiso vigente expedido por autoridad de tránsito. Realizar cambio en las características que identifican un vehículo automotor. Cambiar, modificar o adulterar los números de identificación del motor, chasis o serie de un vehículo.) INMOVILIZACIÓN: SI | D16: 337400 | E16: 168700 | F16: 253050
A17: =COUNTIF(ACTIVOS!AN25:$AN$768,B17) -> 0 | B17: B04 | C17: Conducir un vehículo con placas adulteradas, retocadas o alteradas. INMOVILIZACIÓN: SI | D17: 337400 | E17: 168700 | F17: 253050
A18: =COUNTIF(ACTIVOS!AN26:$AN$768,B18) -> 0 | B18: B05 | C18: Conducir un vehículo con una sola placa, o sin el permiso vigente expedido por autoridad de tránsito. INMOVILIZACIÓN: SI | D18: 337400 | E18: 168700 | F18: 253050
A19: =COUNTIF(ACTIVOS!AN27:$AN$768,B19) -> 0 | B19: B06 | C19: Conducir un vehículo con placas falsas. En los casos B1, B2, B3, B4, B5 y B6 los vehículos serán inmovilizados. INMOVILIZACIÓN: SI | D19: 337400 | E19: 168700 | F19: 253050
A20: =COUNTIF(ACTIVOS!AN28:$AN$768,B20) -> 0 | B20: B07 | C20: No informar a la autoridad de tránsito competente el cambio de motor o color de un vehículo. En ambos casos, el vehículo será inmovilizado. INMOVILIZACIÓN: SI | D20: 337400 | E20: 168700 | F20: 253050
A21: =COUNTIF(ACTIVOS!AN29:$AN$768,B21) -> 0 | B21: B08 | C21: No pagar el peaje en los sitios establecidos. | D21: 337400 | E21: 168700 | F21: 253050
A22: =COUNTIF(ACTIVOS!AN30:$AN$768,B22) -> 0 | B22: B09 | C22: Utilizar equipos de sonido a volúmenes que incomoden a los pasajeros de un vehículo de servicio público. | D22: 337400 | E22: 168700 | F22: 253050
A23: =COUNTIF(ACTIVOS!AN31:$AN$768,B23) -> 0 | B23: B10 | C23: Conducir un vehículo con vidrios polarizados, entintados u oscurecidos, sin portar el permiso respectivo, de acuerdo a la reglamentación existente sobre la materia o, no llevar el vehículo de servicio público colectivo urbano todos los vidrios transparentes. | D23: 337400 | E23: 168700 | F23: 253050
A24: =COUNTIF(ACTIVOS!AN32:$AN$768,B24) -> 0 | B24: B11 | C24: Conducir un vehículo con propaganda, publicidad o adhesivos en sus vidrios que obstaculicen la visibilidad. | D24: 337400 | E24: 168700 | F24: 253050
A25: =COUNTIF(ACTIVOS!AN33:$AN$768,B25) -> 0 | B25: B12 | C25: No respetar las normas establecidas por la autoridad competente para el tránsito de cortejos fúnebres. | D25: 337400 | E25: 168700 | F25: 253050
A26: =COUNTIF(ACTIVOS!AN34:$AN$768,B26) -> 0 | B26: B13 | C26: No respetar las formaciones de tropas, la marcha de desfiles, procesiones, entierros, filas estudiantiles y las manifestaciones públicas y actividades deportivas, debidamente autorizadas por las autoridades de tránsito. | D26: 337400 | E26: 168700 | F26: 253050
... A36: =COUNTIF(ACTIVOS!AN44:$AN$768,B36) -> 0 | B36: B23 | C36: Utilizar radios, equipos de sonido o de amplificación a volúmenes que superen los decibeles máximos establecidos por las autoridades ambientales. De igual forma utilizar pantallas, proyectores de imagen o similares en la parte delantera de los vehículos, mientras esté en movimiento. | D36: 337400 | E36: 168700 | F36: 253050
A37: =COUNTIF(ACTIVOS!AN45:$AN$768,B37) -> 0 | B37: C01 | C37: Presentar licencia de conducción adulterada o ajena, lo cual dará lugar a la inmovilización del vehículo. (Si procede la inmobilización del vehículo) INMOVILIZACIÓN: SI | D37: 633200 | E37: 316600 | F37: 474900 | G37: CONDUCTOR DE VEHÍCULO AUTOMOTOR
A38: =COUNTIF(ACTIVOS!AN46:$AN$768,B38) -> 0 | B38: C02 | C38: Estacionar un vehículo en los siguientes sitios prohibidos: a) Sobre andenes, zonas verdes o sobre espacio público destinado para peatones, recreación o conservación; b) En vías arterias, autopistas, zonas de seguridad, o dentro de un cruce; c) En vías principales y colectoras en las cuales expresamente se indique la prohibición o la restricción en relación con horarios o tipos de vehículos; d) En puentes, viaductos, túneles, pasos bajos, estructuras elevadas o en cualquiera de los accesos a estos; e) En zonas expresamente destinadas para estacionamiento o parada de cierto tipo de vehículos, incluyendo las paradas de vehículos de servicio público, o para limitados físicos; f) En carriles dedicados al transporte masivo sin autorización; g) A una distancia mayor de treinta (30) centímetros de la acera o mayor a cinco (5) metros de la intersección; h) En doble fila de vehículos estacionados, o frente a hidrantes y entradas de garajes; i) En curvas; j) Donde interfiera con la salida de vehículos estacionados; k) Donde las autoridades de tránsito lo prohíban; l) En zona de seguridad y de protección de la vía férrea, en la vía principal, vías secundarias, apartaderos, estaciones y anexidades férreas; m) En los lugares de comercio u obras de construcción de los perímetros urbanos con el objeto de cargar o descargar, fuera de las zonas y horarios determinados para tal fin. INMOVILIZACIÓN: SI Solamente si este ha sido abandonado, de conformidad con el artículo 127 de la Ley 769 de 2002 | D38: 633200 | E38: 316600 | F38: 474900
A39: =COUNTIF(ACTIVOS!AN47:$AN$768,B39) -> 0 | B39: C03 | C39: Bloquear una calzada o intersección con un vehículo, salvo cuando el bloqueo obedezca a la ocurrencia de un accidente de tránsito. | D39: 633200 | E39: 316600 | F39: 474900
A40: =COUNTIF(ACTIVOS!AN48:$AN$768,B40) -> 0 | B40: C04 | C40: Estacionar un vehículo sin tomar las siguientes precauciones: a) En vías urbanas donde está permitido el estacionamiento, no realizarse lo más cercano posible al andén o al límite lateral de la calzada, esto es no menos de treinta (30) centímetros del andén y a una distancia mínima de cinco (5) metros de intersección;b) En autopistas y zonas rurales, estacionarse dentro de la vía cuando se cuenta con espacios para estacionar por fuera de esta;c) No colocar las señales reflectivas de peligro si es de día o las luces de estacionamiento y señales luminosas de peligro si es de noche;d) En caso de reparaciones en vía pública, en los perímetros rurales, no colocar las señales de peligro a distancia entre cincuenta (50) y cien (100) metros adelante y atrás del vehículo;e) En las zonas de estacionamiento prohibido, permanecer por un tiempo superior a 30 minutos, tiempo necesario para su remolque. | D40: 633200 | E40: 316600 | F40: 474900
A41: =COUNTIF(ACTIVOS!AN49:$AN$768,B41) -> 0 | B41: C05 | C41: No reducir la velocidad a treinta (30) kilómetros por hora en los siguientes casos: a) En lugares de concentración de personas y en zonas residenciales;b) En las zonas escolares en los horarios y días de funcionamiento de la institución educativa;c) Cuando se reduzcan las condiciones de visibilidad;d) Cuando las señales de tránsito así lo ordenen;e) En proximidad a una intersección;f) Cuando transite por cruces de hospitales o terminales de pasajeros. | D41: 633200 | E41: 316600 | F41: 474900
A42: =COUNTIF(ACTIVOS!AN50:$AN$768,B42) -> 0 | B42: C06 | C42: No utilizar el cinturón de seguridad por parte de los ocupantes del vehículo y los cinturones de seguridad en los asientos traseros en los vehículos fabricados a partir del año 2004. | D42: 633200 | E42: 316600 | F42: 474900
A43: =COUNTIF(ACTIVOS!AN51:$AN$768,B43) -> 0 | B43: C07 | C43: Dejar de señalizar: a) Con las luces direccionales la maniobra de giro o de cambio de carril;b) Mediante señales manuales, solo en caso de emergencia, y ante la imposibilidad de utilizar las señales direccionales, para cruzar a la izquierda o cambio de carril, para lo cual sacará el brazo izquierdo y lo extenderá horizontalmente;c) Mediante señales manuales, solo en caso de emergencia, y ante la imposibilidad de utilizar las señales direccionales para indicar cruce a la derecha, cambio de carril, para lo cual sacará el brazo izquierdo formando escuadra con la mano hacia arriba;d) Mediante señales manuales, solo en caso de emergencia, y ante la imposibilidad de utilizar las señales direccionales para indicar reducción de velocidad o detención del vehículo, para lo cual sacará el brazo izquierdo formando escuadra con la mano hacia abajo;e) En carreteras o vías rápidas, la indicación intermitente de la señal direccional por lo menos con sesenta (60) metros de antelación al giro, y en zonas urbanas, por lo menos con treinta (30) metros de antelación;f) Mediante señales manuales al peatón que tiene preferencia al paso de la vía, una vez detenido el vehículo y siempre y cuando esté cruzando por una zona demarcada en vías de baja velocidad. | D43: 633200 | E43: 316600 | F43: 474900
A44: =COUNTIF(ACTIVOS!AN52:$AN$768,B44) -> 0 | B44: C08 | C44: Transitar sin los dispositivos luminosos requeridos; no llevar los vehículos de servicio público y oficial, un aviso visible tanto en el interior como en el exterior en el que se señale el número telefónico del centro de llamadas contratado por la Superintendencia de Puertos y Transporte o los vehículos de servicio público no llevar además marcado en los costados y en el techo el número de la placa o los demás elementos determinados en este código. | D44: 633200 | E44: 316600 | F44: 474900
A45: =COUNTIF(ACTIVOS!AN53:$AN$768,B45) -> 0 | B45: C09 | C45: No respetar las señales de detención en el cruce de una línea férrea a una distancia mínima de cinco (5) metros de la vía férrea o conducir por la vía férrea o por las zonas de protección y seguridad de ella. | D45: 633200 | E45: 316600 | F45: 474900
A46: =COUNTIF(ACTIVOS!AN54:$AN$768,B46) -> 0 | B46: C10 | C46: Conducir un vehículo con una o varias puertas abiertas. | D46: 633200 | E46: 316600 | F46: 474900
A47: =COUNTIF(ACTIVOS!AN55:$AN$768,B47) -> 0 | B47: C11 | C47: No portar como mínimo el siguiente equipo de prevención y seguridad: a) Un gato con capacidad para elevar el vehículo;b) Una cruceta;c) Dos señales de carretera en forma de triángulo en material reflectivo y provistas de soportes para ser colocadas en forma vertical o lámparas de señal de luz amarilla intermitentes o de destello;d) Un botiquín de primeros auxilios;e) Un extintor;f) Dos tacos para bloquear el vehículo;g) Caja de herramienta básica que como mínimo deberá contener: Alicate, destornilladores, llave de expansión y llaves fijas;h) Llanta de repuesto;i) Linterna. | D47: 633200 | E47: 316600 | F47: 474900
A48: =COUNTIF(ACTIVOS!AN56:$AN$768,B48) -> 0 | B48: C12 | C48: Proveer de combustible un vehículo automotor con el motor encendido, con pasajeros a bordo cuando el vehículo es de servicio público de radio de acción nacional, transporte especial y escolar o proveer de combustible un vehículo de radio de acción metropolitano, distrital o municipal mientras que estén prestando el servicio | D48: 633200 | E48: 316600 | F48: 474900
A49: =COUNTIF(ACTIVOS!AN57:$AN$768,B49) -> 0 | B49: C13 | C49: Conducir un vehículo automotor sin las adaptaciones pertinentes, cuando el conductor padece de limitación física. | D49: 633200 | E49: 316600 | F49: 474900
...

Sheet ACTIVOS 2
AO1: Código: F-DM-45
AO2: Versión: 02 | AP2: Pág.: 1 de 1
AO3: Fecha emisión: 1/03/2017
AO4: Última revisión: 25/05/2024
B6: FECHA DE ACTUALIZACION | C6: 45678
B8: CEDULA | C8: NOMBRE | D8: ESTADO ACTUAL | E8: FECHA DE INGRESO | F8: FECHA DE RETIRO | G8: FECHA DE NACIMIENTO | H8: EDAD | I8: GÉNERO | J8: CORREO CORPORATIVO | K8: CARGO | L8: AREA | M8: DEPARTAMENTO | N8: ES CONDUCTOR LABORAL | O8: RODAMIENTO | P8: TIPO | Q8: PLACA | R8: ¿ES PROPIETARIO? | S8: PROPIETARIO ACTUAL | U8: NUMERO VIN | V8: NUMERO MOTOR | W8: MODELO | X8: MARCA | Y8: CILINDRAJE | Z8: KILOMETRAJE | AA8: FECHA DE MATRICULA | AB8: REVISIÓN TECNICO MECANICA | AE8: SOAT | AH8: LICENCIA DE CONDUCCIÓN | AL8: RESTRICCIONES | AM8: CUMPLIMIENTO | AN8: REPORTE DE SINIESTROS VIALES | AO8: TIPO Y ESTADO DE PAGO DE SUS INFRACCIONES DE TRÁNSITO | AP8: OBSERVACIONES | AQ8: VALIDACIÓN RETIRO
S9: NOMBRE | T9: IDENTIFICACIÓN | AB9: ESTADO ACTUAL | AC9: ESTADO ACTUAL_CON ERROR | AD9: FECHA VENCIMIENTO | AE9: ESTADO ACTUAL | AF9: ESTADO ACTUAL_CON ERROR | AG9: FECHA VENCIMIENTO | AH9: CATEGORIA DE LICENCIA PARA LA LABOR | AI9: CATEGORIA ACTUAL | AJ9: FECHA VENCIMIENTO DE LICENCIA PARA LA LABOR | AK9: ESTADO ACTUAL
A10: 1 | B10: 1143849922 | C10: GOMEZ RAMOS LINA MARCELA | D10: =IFERROR(VLOOKUP(B10,#REF!,6,0),"ACTIVO") -> ACTIVO | E10: 45078 | F10: =IFERROR(VLOOKUP(B10,#REF!,5,0),"") | G10: 34230 | H10: =+YEARFRAC(G10,TODAY(),1) -> 32.535191 | I10: Femenino | J10: lmgomez@gane.com.co | K10: ANALISTA CONTABLE DE NOMINA | L10: CONTABILIDAD | M10: FINANCIERO | N10: NO | O10: NO | P10: No tiene | AB10: =IF(AD10<=TODAY(),"Vencida","Vigente") -> Vencida | AC10: =IF(P10="No tiene","No aplica",IF(AD10>$C$6,"Vigente","No Vigente")) -> No aplica | AE10: =IF(AG10<=TODAY(),"Vencida","Vigente") -> Vencida | AF10: =+IF(P10="No tiene","No aplica",IF(AG10>$C$6,"Vigente","No Vigente")) -> No aplica | AK10: =+IF(P10="No tiene","No aplica",IF(AJ10>$C$6,"Vigente","No Vigente")) -> No aplica | AM10: =+COUNTIFS(AC10:AK10,"Vigente") -> 0 | AQ10: =+_xlfn.XLOOKUP(B10,'BD 2025-06-14'!$A$1:$A$700,'BD 2025-06-14'!$B$1:$B$700) -> GOMEZ RAMOS LINA MARCELA
A11: 2 | B11: 66814871 | C11: LASSO ENRIQUEZ ESPERANZA DEL CARMEN | D11: =IFERROR(VLOOKUP(B11,#REF!,6,0),"ACTIVO") -> ACTIVO | E11: 39101 | F11: =IFERROR(VLOOKUP(B11,#REF!,5,0),"") | G11: 25723 | H11: =+YEARFRAC(G11,TODAY(),1) -> 55.825448 | I11: Femenino | J11: elasso@gane.com.co | K11: ANALISTA DE ATRACCION | L11: CULTURA Y DESARROLLO | M11: DIRECCION GENERAL | N11: NO | O11: NO | P11: No tiene | AB11: =IF(AD11<=TODAY(),"Vencida","Vigente") -> Vencida | AC11: =IF(P11="No tiene","No aplica",IF(AD11>$C$6,"Vigente","No Vigente")) -> No aplica | AE11: =IF(AG11<=TODAY(),"Vencida","Vigente") -> Vencida | AF11: =+IF(P11="No tiene","No aplica",IF(AG11>$C$6,"Vigente","No Vigente")) -> No aplica | AK11: =+IF(P11="No tiene","No aplica",IF(AJ11>$C$6,"Vigente","No Vigente")) -> No aplica | AM11: =+COUNTIFS(AC11:AK11,"Vigente") -> 0 | AQ11: =+_xlfn.XLOOKUP(B11,'BD 2025-06-14'!$A$1:$A$700,'BD 2025-06-14'!$B$1:$B$700) -> LASSO ENRIQUEZ ESPERANZA DEL CARMEN
A12: 3 | B12: 66834944 | C12: QUINONES VIERA MIRIAM ELISA | D12: =IFERROR(VLOOKUP(B12,#REF!,6,0),"ACTIVO") -> ACTIVO | E12: 39203 | F12: =IFERROR(VLOOKUP(B12,#REF!,5,0),"") | G12: 26342 | H12: =+YEARFRAC(G12,TODAY(),1) -> 54.129374 | I12: Femenino | J12: mequinones@gane.com.co | K12: ANALISTA DE COMPRAS | L12: LOGISTICA | M12: ADMINISTRATIVO | N12: NO | O12: NO | P12: No tiene | AB12: =IF(AD12<=TODAY(),"Vencida","Vigente") -> Vencida | AC12: =IF(P12="No tiene","No aplica",IF(AD12>$C$6,"Vigente","No Vigente")) -> No aplica | AE12: =IF(AG12<=TODAY(),"Vencida","Vigente") -> Vencida | AF12: =+IF(P12="No tiene","No aplica",IF(AG12>$C$6,"Vigente","No Vigente")) -> No aplica | AK12: =+IF(P12="No tiene","No aplica",IF(AJ12>$C$6,"Vigente","No Vigente")) -> No aplica | AM12: =+COUNTIFS(AC12:AK12,"Vigente") -> 0 | AQ12: =+_xlfn.XLOOKUP(B12,'BD 2025-06-14'!$A$1:$A$700,'BD 2025-06-14'!$B$1:$B$700) -> QUINONES VIERA MIRIAM ELISA
A13: 4 | B13: 31308740 | C13: LABRADA CORTES YUDY ANDREA | D13: =IFERROR(VLOOKUP(B13,#REF!,6,0),"ACTIVO") -> ACTIVO | E13: 42500 | F13: =IFERROR(VLOOKUP(B13,#REF!,5,0),"") | G13: 30982 | H13: =+YEARFRAC(G13,TODAY(),1) -> 41.425761 | I13: Femenino | J13: yalabrada@gane.com.co | K13: ANALISTA DE COMPRAS | L13: LOGISTICA | M13: ADMINISTRATIVO | N13: NO | O13: NO | P13: No tiene | AB13: =IF(AD13<=TODAY(),"Vencida","Vigente") -> Vencida | AC13: =IF(P13="No tiene","No aplica",IF(AD13>$C$6,"Vigente","No Vigente")) -> No aplica | AE13: =IF(AG13<=TODAY(),"Vencida","Vigente") -> Vencida | AF13: =+IF(P13="No tiene","No aplica",IF(AG13>$C$6,"Vigente","No Vigente")) -> No aplica | AK13: =+IF(P13="No tiene","No aplica",IF(AJ13>$C$6,"Vigente","No Vigente")) -> No aplica | AM13: =+COUNTIFS(AC13:AK13,"Vigente") -> 0 | AQ13: =+_xlfn.XLOOKUP(B13,'BD 2025-06-14'!$A$1:$A$700,'BD 2025-06-14'!$B$1:$B$700) -> LABRADA CORTES YUDY ANDREA
A14: 5 | B14: 29106748 | C14: ARRECHEA MOSQUERA CARMEN SEIDAD | D14: =IFERROR(VLOOKUP(B14,#REF!,6,0),"ACTIVO") -> ACTIVO | E14: 42537 | F14: =IFERROR(VLOOKUP(B14,#REF!,5,0),"") | G14: 28687 | H14: =+YEARFRAC(G14,TODAY(),1) -> 47.710454 | I14: Femenino | J14: csarrechea@gane.com.co | K14: ANALISTA DE COMPRAS | L14: LOGISTICA | M14: ADMINISTRATIVO | N14: NO | O14: NO | P14: No tiene | AB14: =IF(AD14<=TODAY(),"Vencida","Vigente") -> Vencida | AC14: =IF(P14="No tiene","No aplica",IF(AD14>$C$6,"Vigente","No Vigente")) -> No aplica | AE14: =IF(AG14<=TODAY(),"Vencida","Vigente") -> Vencida | AF14: =+IF(P14="No tiene","No aplica",IF(AG14>$C$6,"Vigente","No Vigente")) -> No aplica | AK14: =+IF(P14="No tiene","No aplica",IF(AJ14>$C$6,"Vigente","No Vigente")) -> No aplica | AM14: =+COUNTIFS(AC14:AK14,"Vigente") -> 0 | AQ14: =+_xlfn.XLOOKUP(B14,'BD 2025-06-14'!$A$1:$A$700,'BD 2025-06-14'!$B$1:$B$700) -> ARRECHEA MOSQUERA CARMEN SEIDAD
A15: 6 | B15: 31307286 | C15: CASTANO VALLEJO VERONICA | D15: =IFERROR(VLOOKUP(B15,#REF!,6,0),"ACTIVO") -> ACTIVO | E15: 39762 | F15: =IFERROR(VLOOKUP(B15,#REF!,5,0),"") | G15: 30925 | H15: =+YEARFRAC(G15,TODAY(),1) -> 41.581816 | I15: Femenino | J15: vcastano@gane.com.co | K15: ANALISTA DE CONTABILIDAD | L15: CONTABILIDAD | M15: FINANCIERO | N15: NO | O15: NO | P15: No tiene | AB15: =IF(AD15<=TODAY(),"Vencida","Vigente") -> Vencida | AC15: =IF(P15="No tiene","No aplica",IF(AD15>$C$6,"Vigente","No Vigente")) -> No aplica | AE15: =IF(AG15<=TODAY(),"Vencida","Vigente") -> Vencida | AF15: =+IF(P15="No tiene","No aplica",IF(AG15>$C$6,"Vigente","No Vigente")) -> No aplica | AK15: =+IF(P15="No tiene","No aplica",IF(AJ15>$C$6,"Vigente","No Vigente")) -> No aplica | AM15: =+COUNTIFS(AC15:AK15,"Vigente") -> 0 | AQ15: =+_xlfn.XLOOKUP(B15,'BD 2025-06-14'!$A$1:$A$700,'BD 2025-06-14'!$B$1:$B$700) -> CASTANO VALLEJO VERONICA
A16: 7 | B16: 1003804381 | C16: BUITRAGO ALVAREZ EDWARD ANDRES | D16: =IFERROR(VLOOKUP(B16,#REF!,6,0),"ACTIVO") -> ACTIVO | E16: 45363 | F16: =IFERROR(VLOOKUP(B16,#REF!,5,0),"") | G16: 37030 | H16: =+YEARFRAC(G16,TODAY(),1) -> 24.869208 | I16: Masculino | J16: eabuitrago@gane.com.co | K16: ANALISTA DE CONTABILIDAD | L16: CONTABILIDAD | M16: FINANCIERO | N16: NO | O16: NO | P16: No tiene | AB16: =IF(AD16<=TODAY(),"Vencida","Vigente") -> Vencida | AC16: =IF(P16="No tiene","No aplica",IF(AD16>$C$6,"Vigente","No Vigente")) -> No aplica | AE16: =IF(AG16<=TODAY(),"Vencida","Vigente") -> Vencida | AF16: =+IF(P16="No tiene","No aplica",IF(AG16>$C$6,"Vigente","No Vigente")) -> No aplica | AK16: =+IF(P16="No tiene","No aplica",IF(AJ16>$C$6,"Vigente","No Vigente")) -> No aplica | AM16: =+COUNTIFS(AC16:AK16,"Vigente") -> 0 | AQ16: =+_xlfn.XLOOKUP(B16,'BD 2025-06-14'!$A$1:$A$700,'BD 2025-06-14'!$B$1:$B$700) -> BUITRAGO ALVAREZ EDWARD ANDRES
A17: 8 | B17: 1082690474 | C17: CABEZAS CABEZAS RODDY GUISSEPPI | D17: =IFERROR(VLOOKUP(B17,#REF!,6,0),"ACTIVO") -> ACTIVO | E17: 45404 | F17: =IFERROR(VLOOKUP(B17,#REF!,5,0),"") | G17: 33566 | H17: =+YEARFRAC(G17,TODAY(),1) -> 34.351814 | I17: Masculino | J17: rgcabezas@gane.com.co | K17: ANALISTA DE CONTABILIDAD | L17: CONTABILIDAD | M17: FINANCIERO | N17: NO | O17: NO | P17: No tiene | AB17: =IF(AD17<=TODAY(),"Vencida","Vigente") -> Vencida | AC17: =IF(P17="No tiene","No aplica",IF(AD17>$C$6,"Vigente","No Vigente")) -> No aplica | AE17: =IF(AG17<=TODAY(),"Vencida","Vigente") -> Vencida | AF17: =+IF(P17="No tiene","No aplica",IF(AG17>$C$6,"Vigente","No Vigente")) -> No aplica | AK17: =+IF(P17="No tiene","No aplica",IF(AJ17>$C$6,"Vigente","No Vigente")) -> No aplica | AM17: =+COUNTIFS(AC17:AK17,"Vigente") -> 0 | AQ17: =+_xlfn.XLOOKUP(B17,'BD 2025-06-14'!$A$1:$A$700,'BD 2025-06-14'!$B$1:$B$700) -> CABEZAS CABEZAS RODDY GUISSEPPI
A18: 9 | B18: 1020103002 | C18: MOSQUERA POTES KATHERINE DAYANA | D18: =IFERROR(VLOOKUP(B18,#REF!,6,0),"ACTIVO") -> ACTIVO | E18: 45629 | F18: =IFERROR(VLOOKUP(B18,#REF!,5,0),"") | G18: 38056 | H18: =+YEARFRAC(G18,TODAY(),1) -> 22.058207 | I18: Femenino | J18: kdmosquera@gane.com.co | K18: ANALISTA DE CONTABILIDAD | L18: CONTABILIDAD | M18: FINANCIERO | N18: NO | O18: NO | P18: No tiene | AB18: =IF(AD18<=TODAY(),"Vencida","Vigente") -> Vencida | AC18: =IF(P18="No tiene","No aplica",IF(AD18>$C$6,"Vigente","No Vigente")) -> No aplica | AE18: =IF(AG18<=TODAY(),"Vencida","Vigente") -> Vencida | AF18: =+IF(P18="No tiene","No aplica",IF(AG18>$C$6,"Vigente","No Vigente")) -> No aplica | AK18: =+IF(P18="No tiene","No aplica",IF(AJ18>$C$6,"Vigente","No Vigente")) -> No aplica | AM18: =+COUNTIFS(AC18:AK18,"Vigente") -> 0 | AQ18: =+_xlfn.XLOOKUP(B18,'BD 2025-06-14'!$A$1:$A$700,'BD 2025-06-14'!$B$1:$B$700) -> MOSQUERA POTES KATHERINE DAYANA
A19: 10 | B19: 1006166424 | C19: PERDOMO COLINA LINA MARCELA | D19: =IFERROR(VLOOKUP(B19,#REF!,6,0),"ACTIVO") -> ACTIVO | E19: 45664 | F19: =IFERROR(VLOOKUP(B19,#REF!,5,0),"") | G19: 36567 | H19: =+YEARFRAC(G19,TODAY(),1) -> 26.134861 | I19: Femenino | J19: lmperdomo@gane.com.co | K19: ANALISTA DE CONTABILIDAD | L19: CONTABILIDAD | M19: FINANCIERO | N19: NO | O19: NO | P19: No tiene | AB19: =IF(AD19<=TODAY(),"Vencida","Vigente") -> Vencida | AC19: =IF(P19="No tiene","No aplica",IF(AD19>$C$6,"Vigente","No Vigente")) -> No aplica | AE19: =IF(AG19<=TODAY(),"Vencida","Vigente") -> Vencida | AF19: =+IF(P19="No tiene","No aplica",IF(AG19>$C$6,"Vigente","No Vigente")) -> No aplica | AK19: =+IF(P19="No tiene","No aplica",IF(AJ19>$C$6,"Vigente","No Vigente")) -> No aplica | AM19: =+COUNTIFS(AC19:AK19,"Vigente") -> 0 | AQ19: =+_xlfn.XLOOKUP(B19,'BD 2025-06-14'!$A$1:$A$700,'BD 2025-06-14'!$B$1:$B$700) -> PERDOMO COLINA LINA MARCELA
A20: 11 | B20: 1118284356 | C20: CARDONA HERNANDEZ IVAN FELIPE | D20: =IFERROR(VLOOKUP(B20,#REF!,6,0),"ACTIVO") -> ACTIVO | E20: 39479 | F20: =IFERROR(VLOOKUP(B20,#REF!,5,0),"") | G20: 31122 | H20: =+YEARFRAC(G20,TODAY(),1) -> 41.044459 | I20: Masculino | J20: fcardona@gane.com.co | K20: ANALISTA DE ESCRUTINIO | L20: ESCRUTINIO | M20: ADMINISTRATIVO | N20: NO | O20: NO | P20: No tiene | AB20: =IF(AD20<=TODAY(),"Vencida","Vigente") -> Vencida | AC20: =IF(P20="No tiene","No aplica",IF(AD20>$C$6,"Vigente","No Vigente")) -> No aplica | AE20: =IF(AG20<=TODAY(),"Vencida","Vigente") -> Vencida | AF20: =+IF(P20="No tiene","No aplica",IF(AG20>$C$6,"Vigente","No Vigente")) -> No aplica | AK20: =+IF(P20="No tiene","No aplica",IF(AJ20>$C$6,"Vigente","No Vigente")) -> No aplica | AM20: =+COUNTIFS(AC20:AK20,"Vigente") -> 0 | AQ20: =+_xlfn.XLOOKUP(B20,'BD 2025-06-14'!$A$1:$A$700,'BD 2025-06-14'!$B$1:$B$700) -> CARDONA HERNANDEZ IVAN FELIPE
A21: 12 | B21: 1107102399 | C21: ZAMBRANO MONTOYA OSCAR ANDRES | D21: =IFERROR(VLOOKUP(B21,#REF!,6,0),"ACTIVO") -> ACTIVO | E21: 43759 | F21: =IFERROR(VLOOKUP(B21,#REF!,5,0),"") | G21: 35338 | H21: =+YEARFRAC(G21,TODAY(),1) -> 29.499691 | I21: Masculino | J21: ozambrano@gane.com.co | K21: ANALISTA DE MONITOREO | L21: OPERACIONES TIC | M21: TIC | N21: NO | O21: NO | P21: No tiene | AB21: =IF(AD21<=TODAY(),"Vencida","Vigente") -> Vencida | AC21: =IF(P21="No tiene","No aplica",IF(AD21>$C$6,"Vigente","No Vigente")) -> No aplica | AE21: =IF(AG21<=TODAY(),"Vencida","Vigente") -> Vencida | AF21: =+IF(P21="No tiene","No aplica",IF(AG21>$C$6,"Vigente","No Vigente")) -> No aplica | AK21: =+IF(P21="No tiene","No aplica",IF(AJ21>$C$6,"Vigente","No Vigente")) -> No aplica | AM21: =+COUNTIFS(AC21:AK21,"Vigente") -> 0 | AQ21: =+_xlfn.XLOOKUP(B21,'BD 2025-06-14'!$A$1:$A$700,'BD 2025-06-14'!$B$1:$B$700) -> ZAMBRANO MONTOYA OSCAR ANDRES
... A23: 14 | B23: 1143926109 | C23: MENA MOSQUERA CRISTIAN MARLON | D23: =IFERROR(VLOOKUP(B23,#REF!,6,0),"ACTIVO") -> ACTIVO | E23: 44789 | F23: =IFERROR(VLOOKUP(B23,#REF!,5,0),"") | G23: 32599 | H23: =+YEARFRAC(G23,TODAY(),1) -> 37.000648 | I23: Masculino | J23: cmmena@gane.com.co | K23: ANALISTA DE MONITOREO | L23: OPERACIONES TIC | M23: TIC | N23: NO | O23: NO | P23: No tiene | AB23: =IF(AD23<=TODAY(),"Vencida","Vigente") -> Vencida | AC23: =IF(P23="No tiene","No aplica",IF(AD23>$C$6,"Vigente","No Vigente")) -> No aplica | AE23: =IF(AG23<=TODAY(),"Vencida","Vigente") -> Vencida | AF23: =+IF(P23="No tiene","No aplica",IF(AG23>$C$6,"Vigente","No Vigente")) -> No aplica | AK23: =+IF(P23="No tiene","No aplica",IF(AJ23>$C$6,"Vigente","No Vigente")) -> No aplica | AM23: =+COUNTIFS(AC23:AK23,"Vigente") -> 0 | AQ23: =+_xlfn.XLOOKUP(B23,'BD 2025-06-14'!$A$1:$A$700,'BD 2025-06-14'!$B$1:$B$700) -> MENA MOSQUERA CRISTIAN MARLON
A24: 15 | B24: 4883086 | C24: TORRES MEJIA CARLOS | D24: =IFERROR(VLOOKUP(B24,#REF!,6,0),"ACTIVO") -> ACTIVO | E24: 42128 | F24: =IFERROR(VLOOKUP(B24,#REF!,5,0),"") | G24: 24327 | H24: =+YEARFRAC(G24,TODAY(),1) -> 59.647487 | I24: Masculino | J24: ctorres@gane.com.co | K24: ANALISTA DE SEGURIDAD | L24: SEGURIDAD | M24: ADMINISTRATIVO | N24: SI | O24: SI | P24: Moto | Q24: TFK64G | R24: Si | U24: 9FMKC3591RF000988 | V24: KC35E-A-3044394 | W24: 2024 | X24: HONDA | Y24: 162 | AA24: 45138 | AB24: =IF(AD24<=TODAY(),"Vencida","Vigente") -> Vigente | AC24: =IF(P24="No tiene","No aplica",IF(AD24>$C$6,"Vigente","No Vigente")) -> Vigente | AD24: 46229 | AE24: =IF(AG24<=TODAY(),"Vencida","Vigente") -> Vigente | AF24: =+IF(P24="No tiene","No aplica",IF(AG24>$C$6,"Vigente","No Vigente")) -> Vigente | AG24: 46230 | AH24: A2 | AI24: A2 (09/05/2032) B1 (24/01/2024) C1 (29/04/2017) | AJ24: 48343 | AK24: =+IF(P24="No tiene","No aplica",IF(AJ24>$C$6,"Vigente","No Vigente")) -> Vigente | AM24: =+COUNTIFS(AC24:AK24,"Vigente") -> 4 | AP24: Debe expedir RTM a los 2 años a partir de la fecha de matricula 31/07/2023 | AQ24: =+_xlfn.XLOOKUP(B24,'BD 2025-06-14'!$A$1:$A$700,'BD 2025-06-14'!$B$1:$B$700) -> TORRES MEJIA CARLOS
A25: 16 | B25: 16843161 | C25: RODRIGUEZ OSPINA IVAN ANDRES | D25: =IFERROR(VLOOKUP(B25,#REF!,6,0),"ACTIVO") -> ACTIVO | E25: 43306 | F25: =IFERROR(VLOOKUP(B25,#REF!,5,0),"") | G25: 29863 | H25: =+YEARFRAC(G25,TODAY(),1) -> 44.491399 | I25: Masculino | J25: iarodriguez@gane.com.co | K25: ANALISTA DE SEGURIDAD | L25: SEGURIDAD | M25: ADMINISTRATIVO | N25: SI | O25: SI | P25: Moto | Q25: CNM60H | R25: No | S25: OSSA LASSO MARIA ALEJANDRA | T25: 1113522508 | U25: 9GJB37PF7SP030555 | V25: PFXWRL53980 | W25: 2025 | X25: BAJAJ | Y25: 102 | AA25: 45450 | AB25: =IF(AD25<=TODAY(),"Vencida","Vigente") -> Vigente | AC25: =IF(P25="No tiene","No aplica",IF(AD25>$C$6,"Vigente","No Vigente")) -> Vigente | AD25: 46180 | AE25: =IF(AG25<=TODAY(),"Vencida","Vigente") -> Vigente | AF25: =+IF(P25="No tiene","No aplica",IF(AG25>$C$6,"Vigente","No Vigente")) -> Vigente | AG25: 46179 | AH25: A2 | AI25: B1 27/12/2027 | AJ25: 49007 | AK25: =+IF(P25="No tiene","No aplica",IF(AJ25>$C$6,"Vigente","No Vigente")) -> Vigente | AM25: =+COUNTIFS(AC25:AK25,"Vigente") -> 4 | AP25: Debe expedir RTM a los 2 años a partir de la fecha de matricula 07/06/2024 | AQ25: =+_xlfn.XLOOKUP(B25,'BD 2025-06-14'!$A$1:$A$700,'BD 2025-06-14'!$B$1:$B$700) -> RODRIGUEZ OSPINA IVAN ANDRES
A26: 17 | B26: 1108645085 | C26: ROJAS LAMPREA GABRIELA | D26: =IFERROR(VLOOKUP(B26,#REF!,6,0),"ACTIVO") -> ACTIVO | E26: 45476 | F26: =IFERROR(VLOOKUP(B26,#REF!,5,0),"") | G26: 39894 | H26: =+YEARFRAC(G26,TODAY(),1) -> 17.027989 | I26: Femenino | J26: grojas@gane.com.co | K26: APRENDIZ SENA | L26: LOGISTICA | M26: ADMINISTRATIVO | N26: NO | O26: NO | P26: No tiene | AB26: =IF(AD26<=TODAY(),"Vencida","Vigente") -> Vencida | AC26: =IF(P26="No tiene","No aplica",IF(AD26>$C$6,"Vigente","No Vigente")) -> No aplica | AE26: =IF(AG26<=TODAY(),"Vencida","Vigente") -> Vencida | AF26: =+IF(P26="No tiene","No aplica",IF(AG26>$C$6,"Vigente","No Vigente")) -> No aplica | AK26: =+IF(P26="No tiene","No aplica",IF(AJ26>$C$6,"Vigente","No Vigente")) -> No aplica | AM26: =+COUNTIFS(AC26:AK26,"Vigente") -> 0 | AQ26: =+_xlfn.XLOOKUP(B26,'BD 2025-06-14'!$A$1:$A$700,'BD 2025-06-14'!$B$1:$B$700) -> ROJAS LAMPREA GABRIELA
A27: 18 | B27: 1144105721 | C27: MONTENEGRO TRUQUE CAROLINA | D27: =IFERROR(VLOOKUP(B27,#REF!,6,0),"ACTIVO") -> ACTIVO | E27: 45516 | F27: =IFERROR(VLOOKUP(B27,#REF!,5,0),"") | G27: 36149 | H27: =+YEARFRAC(G27,TODAY(),1) -> 27.280589 | I27: Femenino | J27: cmontenegro@gane.com.co | K27: APRENDIZ SENA | L27: OPERACIONES COMERCIALES | M27: COMERCIAL | N27: NO | O27: NO | P27: No tiene | AB27: =IF(AD27<=TODAY(),"Vencida","Vigente") -> Vencida | AC27: =IF(P27="No tiene","No aplica",IF(AD27>$C$6,"Vigente","No Vigente")) -> No aplica | AE27: =IF(AG27<=TODAY(),"Vencida","Vigente") -> Vencida | AF27: =+IF(P27="No tiene","No aplica",IF(AG27>$C$6,"Vigente","No Vigente")) -> No aplica | AK27: =+IF(P27="No tiene","No aplica",IF(AJ27>$C$6,"Vigente","No Vigente")) -> No aplica | AM27: =+COUNTIFS(AC27:AK27,"Vigente") -> 0 | AQ27: =+_xlfn.XLOOKUP(B27,'BD 2025-06-14'!$A$1:$A$700,'BD 2025-06-14'!$B$1:$B$700) -> MONTENEGRO TRUQUE CAROLINA
A28: 19 | B28: 1111547929 | C28: ARANGO VELASQUEZ KEVIN GABRIEL | D28: =IFERROR(VLOOKUP(B28,#REF!,6,0),"ACTIVO") -> ACTIVO | E28: 45537 | F28: =IFERROR(VLOOKUP(B28,#REF!,5,0),"") | G28: 39724 | H28: =+YEARFRAC(G28,TODAY(),1) -> 17.491499 | I28: Masculino | J28: kgarango@gane.com.co | K28: APRENDIZ SENA | L28: OPERACIONES COMERCIALES | M28: COMERCIAL | N28: NO | O28: NO | P28: No tiene | AB28: =IF(AD28<=TODAY(),"Vencida","Vigente") -> Vencida | AC28: =IF(P28="No tiene","No aplica",IF(AD28>$C$6,"Vigente","No Vigente")) -> No aplica | AE28: =IF(AG28<=TODAY(),"Vencida","Vigente") -> Vencida | AF28: =+IF(P28="No tiene","No aplica",IF(AG28>$C$6,"Vigente","No Vigente")) -> No aplica | AK28: =+IF(P28="No tiene","No aplica",IF(AJ28>$C$6,"Vigente","No Vigente")) -> No aplica | AM28: =+COUNTIFS(AC28:AK28,"Vigente") -> 0 | AQ28: =+_xlfn.XLOOKUP(B28,'BD 2025-06-14'!$A$1:$A$700,'BD 2025-06-14'!$B$1:$B$700) -> ARANGO VELASQUEZ KEVIN GABRIEL
A29: 20 | B29: 1109671237 | C29: ZORNOSA GALLO SAMANTHA | D29: =IFERROR(VLOOKUP(B29,#REF!,6,0),"ACTIVO") -> ACTIVO | E29: 45544 | F29: =IFERROR(VLOOKUP(B29,#REF!,5,0),"") | G29: 39815 | H29: =+YEARFRAC(G29,TODAY(),1) -> 17.244296 | I29: Femenino | J29: szgallo@gane.com.co | K29: APRENDIZ SENA | L29: OPERACIONES COMERCIALES | M29: COMERCIAL | N29: NO | O29: NO | P29: No tiene | AB29: =IF(AD29<=TODAY(),"Vencida","Vigente") -> Vencida | AC29: =IF(P29="No tiene","No aplica",IF(AD29>$C$6,"Vigente","No Vigente")) -> No aplica | AE29: =IF(AG29<=TODAY(),"Vencida","Vigente") -> Vencida | AF29: =+IF(P29="No tiene","No aplica",IF(AG29>$C$6,"Vigente","No Vigente")) -> No aplica | AK29: =+IF(P29="No tiene","No aplica",IF(AJ29>$C$6,"Vigente","No Vigente")) -> No aplica | AM29: =+COUNTIFS(AC29:AK29,"Vigente") -> 0 | AQ29: =+_xlfn.XLOOKUP(B29,'BD 2025-06-14'!$A$1:$A$700,'BD 2025-06-14'!$B$1:$B$700) -> ZORNOSA GALLO SAMANTHA
A30: 21 | B30: 1108644972 | C30: ROJAS SAAVEDRA NATALIA | D30: =IFERROR(VLOOKUP(B30,#REF!,6,0),"ACTIVO") -> ACTIVO | E30: 45551 | F30: =IFERROR(VLOOKUP(B30,#REF!,5,0),"") | G30: 39934 | H30: =+YEARFRAC(G30,TODAY(),1) -> 16.918467 | I30: Femenino | J30: nrojas@gane.com.co | K30: APRENDIZ SENA | L30: OPERACIONES COMERCIALES | M30: COMERCIAL | N30: NO | O30: NO | P30: No tiene | AB30: =IF(AD30<=TODAY(),"Vencida","Vigente") -> Vencida | AC30: =IF(P30="No tiene","No aplica",IF(AD30>$C$6,"Vigente","No Vigente")) -> No aplica | AE30: =IF(AG30<=TODAY(),"Vencida","Vigente") -> Vencida | AF30: =+IF(P30="No tiene","No aplica",IF(AG30>$C$6,"Vigente","No Vigente")) -> No aplica | AK30: =+IF(P30="No tiene","No aplica",IF(AJ30>$C$6,"Vigente","No Vigente")) -> No aplica | AM30: =+COUNTIFS(AC30:AK30,"Vigente") -> 0 | AQ30: =+_xlfn.XLOOKUP(B30,'BD 2025-06-14'!$A$1:$A$700,'BD 2025-06-14'!$B$1:$B$700) -> ROJAS SAAVEDRA NATALIA
A31: 22 | B31: 1109187542 | C31: MINA CORDOBA MARIA CAMILA | D31: =IFERROR(VLOOKUP(B31,#REF!,6,0),"ACTIVO") -> ACTIVO | E31: 45551 | F31: =IFERROR(VLOOKUP(B31,#REF!,5,0),"") | G31: 38980 | H31: =+YEARFRAC(G31,TODAY(),1) -> 19.529726 | I31: Femenino | J31: mcmina@gane.com.co | K31: APRENDIZ SENA | L31: OPERACIONES COMERCIALES | M31: COMERCIAL | N31: NO | O31: NO | P31: No tiene | AB31: =IF(AD31<=TODAY(),"Vencida","Vigente") -> Vencida | AC31: =IF(P31="No tiene","No aplica",IF(AD31>$C$6,"Vigente","No Vigente")) -> No aplica | AE31: =IF(AG31<=TODAY(),"Vencida","Vigente") -> Vencida | AF31: =+IF(P31="No tiene","No aplica",IF(AG31>$C$6,"Vigente","No Vigente")) -> No aplica | AK31: =+IF(P31="No tiene","No aplica",IF(AJ31>$C$6,"Vigente","No Vigente")) -> No aplica | AM31: =+COUNTIFS(AC31:AK31,"Vigente") -> 0 | AQ31: =+_xlfn.XLOOKUP(B31,'BD 2025-06-14'!$A$1:$A$700,'BD 2025-06-14'!$B$1:$B$700) -> MINA CORDOBA MARIA CAMILA
A32: 23 | B32: 1110294638 | C32: ARCE SANCHEZ GELEN DAYAN | D32: =IFERROR(VLOOKUP(B32,#REF!,6,0),"ACTIVO") -> ACTIVO | E32: 45551 | F32: =IFERROR(VLOOKUP(B32,#REF!,5,0),"") | G32: 39320 | H32: =+YEARFRAC(G32,TODAY(),1) -> 18.59822 | I32: Femenino | J32: gdarce@gane.com.co | K32: APRENDIZ SENA | L32: LOGISTICA | M32: ADMINISTRATIVO | N32: NO | O32: NO | P32: No tiene | AB32: =IF(AD32<=TODAY(),"Vencida","Vigente") -> Vencida | AC32: =IF(P32="No tiene","No aplica",IF(AD32>$C$6,"Vigente","No Vigente")) -> No aplica | AE32: =IF(AG32<=TODAY(),"Vencida","Vigente") -> Vencida | AF32: =+IF(P32="No tiene","No aplica",IF(AG32>$C$6,"Vigente","No Vigente")) -> No aplica | AK32: =+IF(P32="No tiene","No aplica",IF(AJ32>$C$6,"Vigente","No Vigente")) -> No aplica | AM32: =+COUNTIFS(AC32:AK32,"Vigente") -> 0 | AQ32: =+_xlfn.XLOOKUP(B32,'BD 2025-06-14'!$A$1:$A$700,'BD 2025-06-14'!$B$1:$B$700) -> ARCE SANCHEZ GELEN DAYAN
A33: 24 | B33: 1059840437 | C33: FRANKLY RIVERA KENER DANIEL | D33: =IFERROR(VLOOKUP(B33,#REF!,6,0),"ACTIVO") -> ACTIVO | E33: 45588 | F33: =IFERROR(VLOOKUP(B33,#REF!,5,0),"") | G33: 38144 | H33: =+YEARFRAC(G33,TODAY(),1) -> 21.817284 | I33: Masculino | J33: kdfranfly@gane.com.co | K33: APRENDIZ SENA | L33: MERCADEO | M33: COMERCIAL | N33: NO | O33: NO | P33: No tiene | AB33: =IF(AD33<=TODAY(),"Vencida","Vigente") -> Vencida | AC33: =IF(P33="No tiene","No aplica",IF(AD33>$C$6,"Vigente","No Vigente")) -> No aplica | AE33: =IF(AG33<=TODAY(),"Vencida","Vigente") -> Vencida | AF33: =+IF(P33="No tiene","No aplica",IF(AG33>$C$6,"Vigente","No Vigente")) -> No aplica | AK33: =+IF(P33="No tiene","No aplica",IF(AJ33>$C$6,"Vigente","No Vigente")) -> No aplica | AM33: =+COUNTIFS(AC33:AK33,"Vigente") -> 0 | AQ33: =+_xlfn.XLOOKUP(B33,'BD 2025-06-14'!$A$1:$A$700,'BD 2025-06-14'!$B$1:$B$700) -> FRANKLY RIVERA KENER DANIEL
A34: 25 | B34: 1110045753 | C34: VARGAS RUBIO SOFIA | D34: =IFERROR(VLOOKUP(B34,#REF!,6,0),"ACTIVO") -> ACTIVO | E34: 45601 | F34: =IFERROR(VLOOKUP(B34,#REF!,5,0),"") | G34: 39650 | H34: =+YEARFRAC(G34,TODAY(),1) -> 17.694092 | I34: Femenino | J34: svargas@gane.com.co | K34: APRENDIZ SENA | L34: OPERACIONES COMERCIALES | M34: COMERCIAL | N34: NO | O34: NO | P34: No tiene | AB34: =IF(AD34<=TODAY(),"Vencida","Vigente") -> Vencida | AC34: =IF(P34="No tiene","No aplica",IF(AD34>$C$6,"Vigente","No Vigente")) -> No aplica | AE34: =IF(AG34<=TODAY(),"Vencida","Vigente") -> Vencida | AF34: =+IF(P34="No tiene","No aplica",IF(AG34>$C$6,"Vigente","No Vigente")) -> No aplica | AK34: =+IF(P34="No tiene","No aplica",IF(AJ34>$C$6,"Vigente","No Vigente")) -> No aplica | AM34: =+COUNTIFS(AC34:AK34,"Vigente") -> 0 | AQ34: =+_xlfn.XLOOKUP(B34,'BD 2025-06-14'!$A$1:$A$700,'BD 2025-06-14'!$B$1:$B$700) -> VARGAS RUBIO SOFIA
A35: 26 | B35: 7159169 | C35: LOPEZ BRICENO EMILIO ANTONIO | D35: =IFERROR(VLOOKUP(B35,#REF!,6,0),"ACTIVO") -> ACTIVO | E35: 45601 | F35: =IFERROR(VLOOKUP(B35,#REF!,5,0),"") | G35: 39470 | H35: =+YEARFRAC(G35,TODAY(),1) -> 18.186888 | I35: Masculino | J35: elopez@gane.com.co | K35: APRENDIZ SENA | L35: OPERACIONES COMERCIALES | M35: COMERCIAL | N35: NO | O35: NO | P35: No tiene | AB35: =IF(AD35<=TODAY(),"Vencida","Vigente") -> Vencida | AC35: =IF(P35="No tiene","No aplica",IF(AD35>$C$6,"Vigente","No Vigente")) -> No aplica | AE35: =IF(AG35<=TODAY(),"Vencida","Vigente") -> Vencida | AF35: =+IF(P35="No tiene","No aplica",IF(AG35>$C$6,"Vigente","No Vigente")) -> No aplica | AK35: =+IF(P35="No tiene","No aplica",IF(AJ35>$C$6,"Vigente","No Vigente")) -> No aplica | AM35: =+COUNTIFS(AC35:AK35,"Vigente") -> 0 | AQ35: =+_xlfn.XLOOKUP(B35,'BD 2025-06-14'!$A$1:$A$700,'BD 2025-06-14'!$B$1:$B$700) -> LOPEZ BRICENO EMILIO ANTONIO
A36: 27 | B36: 1111548805 | C36: MUNOZ MEDINA JUAN DAVID | D36: =IFERROR(VLOOKUP(B36,#REF!,6,0),"ACTIVO") -> ACTIVO | E36: 45604 | F36: =IFERROR(VLOOKUP(B36,#REF!,5,0),"") | G36: 39954 | H36: =+YEARFRAC(G36,TODAY(),1) -> 16.863706 | I36: Masculino | J36: jdmuðoz@gane.com.co | K36: APRENDIZ SENA | L36: TESORERIA | M36: FINANCIERO | N36: NO | O36: NO | P36: No tiene | AB36: =IF(AD36<=TODAY(),"Vencida","Vigente") -> Vencida | AC36: =IF(P36="No tiene","No aplica",IF(AD36>$C$6,"Vigente","No Vigente")) -> No aplica | AE36: =IF(AG36<=TODAY(),"Vencida","Vigente") -> Vencida | AF36: =+IF(P36="No tiene","No aplica",IF(AG36>$C$6,"Vigente","No Vigente")) -> No aplica | AK36: =+IF(P36="No tiene","No aplica",IF(AJ36>$C$6,"Vigente","No Vigente")) -> No aplica | AM36: =+COUNTIFS(AC36:AK36,"Vigente") -> 0 | AQ36: =+_xlfn.XLOOKUP(B36,'BD 2025-06-14'!$A$1:$A$700,'BD 2025-06-14'!$B$1:$B$700) -> MUNOZ MEDINA JUAN DAVID
A37: 28 | B37: 1111659067 | C37: SINISTERRA RIASCOS MELISSA | D37: =IFERROR(VLOOKUP(B37,#REF!,6,0),"ACTIVO") -> ACTIVO | E37: 45621 | F37: =IFERROR(VLOOKUP(B37,#REF!,5,0),"") | G37: 36923 | H37: =+YEARFRAC(G37,TODAY(),1) -> 25.162174 | I37: Femenino | J37: msinisterra@gane.com.co | K37: APRENDIZ SENA | L37: TESORERIA | M37: FINANCIERO | N37: NO | O37: NO | P37: No tiene | AB37: =IF(AD37<=TODAY(),"Vencida","Vigente") -> Vencida | AC37: =IF(P37="No tiene","No aplica",IF(AD37>$C$6,"Vigente","No Vigente")) -> No aplica | AE37: =IF(AG37<=TODAY(),"Vencida","Vigente") -> Vencida | AF37: =+IF(P37="No tiene","No aplica",IF(AG37>$C$6,"Vigente","No Vigente")) -> No aplica | AK37: =+IF(P37="No tiene","No aplica",IF(AJ37>$C$6,"Vigente","No Vigente")) -> No aplica | AM37: =+COUNTIFS(AC37:AK37,"Vigente") -> 0 | AQ37: =+_xlfn.XLOOKUP(B37,'BD 2025-06-14'!$A$1:$A$700,'BD 2025-06-14'!$B$1:$B$700) -> SINISTERRA RIASCOS MELISSA
... A67: 58 | B67: 1023026154 | C67: RAMIREZ CHACON INGRID GINETH | D67: =IFERROR(VLOOKUP(B67,#REF!,6,0),"ACTIVO") -> ACTIVO | E67: 45187 | F67: =IFERROR(VLOOKUP(B67,#REF!,5,0),"") | G67: 35728 | H67: =+YEARFRAC(G67,TODAY(),1) -> 28.433878 | I67: Femenino | J67: igramirez@gane.com.co | K67: ASESOR DE CARTERA | L67: TESORERIA | M67: FINANCIERO | N67: NO | O67: NO | P67: No tiene | AB67: =IF(AD67<=TODAY(),"Vencida","Vigente") -> Vencida | AC67: =IF(P67="No tiene","No aplica",IF(AD67>$C$6,"Vigente","No Vigente")) -> No aplica | AE67: =IF(AG67<=TODAY(),"Vencida","Vigente") -> Vencida | AF67: =+IF(P67="No tiene","No aplica",IF(AG67>$C$6,"Vigente","No Vigente")) -> No aplica | AK67: =+IF(P67="No tiene","No aplica",IF(AJ67>$C$6,"Vigente","No Vigente")) -> No aplica | AM67: =+COUNTIFS(AC67:AK67,"Vigente") -> 0 | AQ67: =+_xlfn.XLOOKUP(B67,'BD 2025-06-14'!$A$1:$A$700,'BD 2025-06-14'!$B$1:$B$700) -> RAMIREZ CHACON INGRID GINETH
A68: 59 | B68: 1130590251 | C68: PRADA VILLA EDGAR HERNAN | D68: =IFERROR(VLOOKUP(B68,#REF!,6,0),"ACTIVO") -> ACTIVO | E68: 45614 | F68: =IFERROR(VLOOKUP(B68,#REF!,5,0),"") | G68: 31704 | H68: =+YEARFRAC(G68,TODAY(),1) -> 39.450351 | I68: Masculino | J68: ehprada@gane.com.co | K68: ASESOR DE VENTAS - BETPLAY | L68: LINEA DE NEGOCIOS | M68: COMERCIAL | N68: SI | O68: SI | P68: Moto | Q68: IWH85C | R68: No | S68: Lopez Javier | T68: 14835665 | U68: 9FMPCG62XBF006325 | V68: SDH150FMG-2A*A5807995* | W68: 2011 | X68: HONDA | Y68: 97 | AA68: 40637 | AB68: =IF(AD68<=TODAY(),"Vencida","Vigente") -> Vencida | AC68: =IF(P68="No tiene","No aplica",IF(AD68>$C$6,"Vigente","No Vigente")) -> Vigente | AD68: 46049 | AE68: =IF(AG68<=TODAY(),"Vencida","Vigente") -> Vencida | AF68: =+IF(P68="No tiene","No aplica",IF(AG68>$C$6,"Vigente","No Vigente")) -> Vigente | AG68: 46040 | AH68: A2 | AI68: A2 | AJ68: 48982 | AK68: =+IF(P68="No tiene","No aplica",IF(AJ68>$C$6,"Vigente","No Vigente")) -> Vigente | AM68: =+COUNTIFS(AC68:AK68,"Vigente") -> 3 | AQ68: =+_xlfn.XLOOKUP(B68,'BD 2025-06-14'!$A$1:$A$700,'BD 2025-06-14'!$B$1:$B$700) -> PRADA VILLA EDGAR HERNAN
A69: 60 | B69: 1130658285 | C69: FIGUEROA DELGADO RODOLFO | D69: =IFERROR(VLOOKUP(B69,#REF!,6,0),"ACTIVO") -> ACTIVO | E69: 45748 | F69: =IFERROR(VLOOKUP(B69,#REF!,5,0),"") | G69: 32115 | H69: =+YEARFRAC(G69,TODAY(),1) -> 38.324435 | I69: Masculino | J69: rfigueroa@gane.com.co | K69: ASESOR DE VENTAS - BETPLAY | L69: LINEA DE NEGOCIOS | M69: COMERCIAL | N69: SI | O69: SI | P69: Moto | Q69: KLN45F | R69: Si | U69: 9F2C11257M5003756 | V69: ZS154FMI-38M103618 | W69: 2021 | X69: AKT | Y69: 124 | AA69: 44074 | AB69: =IF(AD69<=TODAY(),"Vencida","Vigente") -> Vencida | AC69: =IF(P69="No tiene","No aplica",IF(AD69>$C$6,"Vigente","No Vigente")) -> Vigente | AD69: 46018 | AE69: =IF(AG69<=TODAY(),"Vencida","Vigente") -> Vencida | AF69: =+IF(P69="No tiene","No aplica",IF(AG69>$C$6,"Vigente","No Vigente")) -> Vigente | AG69: 46018 | AH69: A2 | AI69: A2 (02/11/2032) B2 (24/04/2030) C2 (24/07/2023) | AJ69: 48520 | AK69: =+IF(P69="No tiene","No aplica",IF(AJ69>$C$6,"Vigente","No Vigente")) -> Vigente | AM69: =+COUNTIFS(AC69:AK69,"Vigente") -> 3 | AQ69: =+_xlfn.XLOOKUP(B69,'BD 2025-06-14'!$A$1:$A$700,'BD 2025-06-14'!$B$1:$B$700) -> FIGUEROA DELGADO RODOLFO
A70: 61 | B70: 79849153 | C70: RODRIGUEZ VELASQUEZ JOHN MANUEL | D70: =IFERROR(VLOOKUP(B70,#REF!,6,0),"ACTIVO") -> ACTIVO | E70: 40371 | F70: =IFERROR(VLOOKUP(B70,#REF!,5,0),"") | G70: 27724 | H70: =+YEARFRAC(G70,TODAY(),1) -> 50.346338 | I70: Masculino | J70: jmrodriguez@gane.com.co | K70: ASESOR DE VENTAS - GIROS, PAGOS, RECARGAS | L70: LINEA DE NEGOCIOS | M70: COMERCIAL | N70: SI | O70: SI | P70: Moto | Q70: PRM41G | R70: Si | U70: LC6JCK4P3P0026077 | V70: 157FMJ-3*G2U57080* | W70: 2023 | X70: Suzuki | Y70: 149 | AA70: 45020 | AB70: =IF(AD70<=TODAY(),"Vencida","Vigente") -> Vencida | AC70: =IF(P70="No tiene","No aplica",IF(AD70>$C$6,"Vigente","No Vigente")) -> Vigente | AD70: 46113 | AE70: =IF(AG70<=TODAY(),"Vencida","Vigente") -> Vencida | AF70: =+IF(P70="No tiene","No aplica",IF(AG70>$C$6,"Vigente","No Vigente")) -> Vigente | AG70: 46113 | AH70: A2 | AI70: A2 | AJ70: 49144 | AK70: =+IF(P70="No tiene","No aplica",IF(AJ70>$C$6,"Vigente","No Vigente")) -> Vigente | AM70: =+COUNTIFS(AC70:AK70,"Vigente") -> 3 | AP70: Moto nueva, debe expedir RTM a los 2 años a partir de la fecha de matricula 4/4/2023 | AQ70: =+_xlfn.XLOOKUP(B70,'BD 2025-06-14'!$A$1:$A$700,'BD 2025-06-14'!$B$1:$B$700) -> RODRIGUEZ VELASQUEZ JOHN MANUEL
A71: 62 | B71: 67038967 | C71: SANCHEZ GUTIERREZ ANGEL | D71: =IFERROR(VLOOKUP(B71,#REF!,6,0),"ACTIVO") -> ACTIVO | E71: 41535 | F71: =IFERROR(VLOOKUP(B71,#REF!,5,0),"") | G71: 31309 | H71: =+YEARFRAC(G71,TODAY(),1) -> 40.532464 | I71: Masculino | J71: asanchez@gane.com.co | K71: ASESOR DE VENTAS - GIROS, PAGOS, RECARGAS | L71: LINEA DE NEGOCIOS | M71: COMERCIAL | N71: SI | O71: SI | P71: Moto | Q71: QXP04H | R71: Si | U71: ME4MC5690SA014988 | V71: MC56E2028289 | W71: 2025 | X71: HONDA | Y71: 184 | AA71: 45882 | AB71: =IF(AD71<=TODAY(),"Vencida","Vigente") -> Vigente | AC71: =IF(P71="No tiene","No aplica",IF(AD71>$C$6,"Vigente","No Vigente")) -> Vigente | AD71: 46612 | AE71: =IF(AG71<=TODAY(),"Vencida","Vigente") -> Vigente | AF71: =+IF(P71="No tiene","No aplica",IF(AG71>$C$6,"Vigente","No Vigente")) -> Vigente | AG71: 46246 | AH71: A2 | AI71: A2 | AJ71: 48898 | AK71: =+IF(P71="No tiene","No aplica",IF(AJ71>$C$6,"Vigente","No Vigente")) -> Vigente | AM71: =+COUNTIFS(AC71:AK71,"Vigente") -> 4 | AP71: Reporta cambio de moto el dia 11/12/2025 | AQ71: =+_xlfn.XLOOKUP(B71,'BD 2025-06-14'!$A$1:$A$700,'BD 2025-06-14'!$B$1:$B$700) -> SANCHEZ GUTIERREZ ANGEL
A72: 63 | B72: 1144070871 | C72: ROMAN OCAMPO MILDREY | D72: =IFERROR(VLOOKUP(B72,#REF!,6,0),"ACTIVO") -> ACTIVO | E72: 42888 | F72: =IFERROR(VLOOKUP(B72,#REF!,5,0),"") | G72: 34486 | H72: =+YEARFRAC(G72,TODAY(),1) -> 31.833651 | I72: Femenino | J72: mroman@gane.com.co | K72: ASESOR DE VENTAS - GIROS, PAGOS, RECARGAS | L72: LINEA DE NEGOCIOS | M72: COMERCIAL | N72: SI | O72: SI | P72: Moto | Q72: KLO34E | R72: Si | U72: 9FLU62013HCJ51394 | V72: KN25SR2241927 | W72: 2017 | X72: Kymco | Y72: 125 | AA72: 42788 | AB72: =IF(AD72<=TODAY(),"Vencida","Vigente") -> Vigente | AC72: =IF(P72="No tiene","No aplica",IF(AD72>$C$6,"Vigente","No Vigente")) -> Vigente | AD72: 46236 | AE72: =IF(AG72<=TODAY(),"Vencida","Vigente") -> Vigente | AF72: =+IF(P72="No tiene","No aplica",IF(AG72>$C$6,"Vigente","No Vigente")) -> Vigente | AG72: 46236 | AH72: A2 | AI72: A2 | AJ72: 46448 | AK72: =+IF(P72="No tiene","No aplica",IF(AJ72>$C$6,"Vigente","No Vigente")) -> Vigente | AM72: =+COUNTIFS(AC72:AK72,"Vigente") -> 4 | AQ72: =+_xlfn.XLOOKUP(B72,'BD 2025-06-14'!$A$1:$A$700,'BD 2025-06-14'!$B$1:$B$700) -> ROMAN OCAMPO MILDREY
...

Sheet Conductores
A1: BASE DE DATOS REVISIÓN TECNICO MECANICA Y SOAT | CC1: =TODAY() -> 46113
A2: No. | D2: IDENTIFICACIÓN | E2: NOMBRE | F2: FECHA DE NACIMIENTO | G2: GENERO | H2: ESCOLARIDAD | I2: EDAD | J2: ESTADO CIVIL | K2: CARGO | L2: DEPARTAMENTO | M2: FECHA DE INGRESO A LA EMPRESA | N2: ANTIGÜEDAD (AÑOS) | P2: TIPO DE VEHÍCULO QUE CONDUCE EN MISIÓN O LABOR | Q2: CATEGORIA DE LICENCIA PARA LA LABOR | R2: VIGENCIA LICENCIA PARA LA LABOR | S2: ESTADO DE LICENCIA PARA LA LABOR | T2: FECHA DISCIPLINARIOS | V2: PLACA | W2: NUMERO VIN | X2: NUMERO MOTOR | Y2: MODELO | Z2: MARCA | AA2: CILINDRAJE | AB2: KILOMETRAJE | AC2: FECHA DE MATRICULA | AD2: TIPO | AE2: ¿ES PROPIETARIO? | AF2: PROPIETARIO ACTUAL | AH2: PORCENTAJE BENEFICIO | AJ2: REVISIÓN TECNICO MECANICA | AM2: SOAT | AP2: LICENCIA DE CONDUCCIÓN | AS2: SINIESTROS VIALES EN MISION ULTIMOS 5 AÑOS EN LA LABOR | AT2: CANTIDAD DE SINIESTROS | AU2: MULTAS | AV2: TIPO DE INFRACCIÓN | AW2: ESTADO DE PAGO DE INFRACCIONES | AX2: CAPACITACIONES Y EVALUACIÓN ANUAL SEGURIDAD VIAL | AY2: CAPACITACIÓN PLAN DE EMERGENCIA VIAL | AZ2: TIPO DE VEHÍCULO USO CASA-TRABAJO | BA2: SINIESTROS VIALES CASA A TRABAJO ULTIMOS 5 AÑOS | BB2: CANTIDAD | BC2: OBSERVACIONES OTRAS LICENCIAS | BD2: OBSERVACIONES
T3: SANCIONES | U3: LLAMADOS DE ATENCIÓN | AF3: NOMBRE | AG3: IDENTIFICACIÓN | AH3: SOAT | AI3: RTM | AJ3: ESTADO ACTUAL | AK3: FECHA VENCIMIENTO | AL3: FECHA EJECUCIÓN | AM3: ESTADO ACTUAL | AN3: FECHA VENCIMIENTO | AO3: FECHA EJECUCIÓN | AP3: CATEGORIA | AQ3: FECHA VENCIMIENTO | AR3: ESTADO ACTUAL
A4: 1 | D4: 84451541 | E4: Abella Ramos Jorge Jose | F4: 30248 | G4: MASCULINO | I4: =(CC$1-F4)/365 -> 43.465753 | K4: Auxiliar Operativo - Comercial (Tangibles) | L4: Comercial | M4: 45006 | N4: =(CC$1-M4)/365 -> 3.0328767 | O4: 3052967867 | V4: WVY19D | W4: 9F2B81252GA006082 | X4: 157FMINQ152029 | Y4: 2016 | Z4: AKT | AA4: 125 | AC4: 42298 | AD4: Moto | AE4: Si | AH4: 0.5 | AI4: 1 | AJ4: =IF(AK4>TODAY(),"Vigente","No Vigente") -> No Vigente | AK4: =(AL4+365) -> 45340 | AL4: 44975 | AM4: =IF(AN4>TODAY(),"Vigente","No Vigente") -> No Vigente | AN4: =(AO4+365) -> 45333 | AO4: 44968 | AP4: A2 | AQ4: 45972 | AR4: =IF(AQ4>TODAY(),"Vigente","No Vigente") -> No Vigente | BC4: Tiene licencia B1 (22/10/2023) y C1(22/10/2023) | BD4: Retirado
A5: 2 | D5: 1005943971 | E5: Acevedo Hernandez Aymer Arley | F5: 35204 | G5: MASCULINO | H5: Bachiller academico | I5: =(CC$1-F5)/365 -> 29.887671 | J5: Soltero | K5: Asesor de venta | L5: Comercial | M5: 44062 | N5: =(CC$1-M5)/365 -> 5.6191781 | O5: 312 888 5751 | P5: MOTOCICLETA | Q5: A2 | R5: 47094 | S5: Vigente | T5: 0 | U5: 0 | V5: WVN58E | W5: 9G5JAR056JVHK033 | X5: 9G5JAR056JVHK0033 | Y5: 2018 | Z5: Hero | AA5: 125 | AC5: 43375 | AD5: Moto | AE5: Si | AH5: 0.5 | AI5: 1 | AJ5: Vigente | AK5: 45453 | AL5: 45087 | AM5: Vigente | AN5: 10/16/2024 | AO5: 45215 | AP5: A2 | AQ5: 47094 | AR5: =IF(AQ5>TODAY(),"Vigente","No Vigente") -> Vigente | AU5: No tiene multas | AV5: No | AW5: No | BC5: Retirado | BD5: Retirado
A6: 3 | D6: 16722977 | E6: Agudelo Salazar Jhon Fernando | F6: 23966 | G6: MASCULINO | H6: Tecnico profesional en ingenieria en sistemas | I6: =(CC$1-F6)/365 -> 60.676712 | J6: Casado | K6: Técnico de Soporte | L6: TIC´s | M6: 38874 | N6: =(CC$1-M6)/365 -> 19.832877 | O6: 320 520 8968 | P6: MOTOCICLETA | Q6: A2 | R6: 45097 | S6: Vencida | T6: 2 | V6: LIX28E | W6: 9G5HA11A3HV009618 | X6: HA11EJG9H06606 | Y6: 2017 | Z6: Hero | AA6: 98 | AC6: 42812 | AD6: Moto | AE6: si | AH6: NO APLICA | AI6: NO APLICA | AJ6: =IF(AK6>TODAY(),"Vigente","No Vigente") -> No Vigente | AK6: 45955 | AL6: 45590 | AM6: =IF(AN6>TODAY(),"Vigente","No Vigente") -> No Vigente | AN6: 45951 | AO6: 45587 | AP6: A2 | AQ6: 45097 | AR6: =IF(AQ6>TODAY(),"Vigente","No Vigente") -> No Vigente | AU6: Si | AV6: D02 Conducir sin portar el seguro obligatorio de accidentes de transito. | AW6: Multa del: 21/12/2021 se ecuenta con cobro coactivo - Multa del 25/08/2023 pendiente para pago. | BC6: Restricciones medico laboral para ejercer funciones en motocicleta | BD6: No ha enviado información.
A7: 4 | D7: 71185148 | E7: Aguiar Medardo Alcides | F7: 24353 | G7: MASCULINO | H7: Tecnologo electrico | I7: =(CC$1-F7)/365 -> 59.616438 | J7: Unión Libre | K7: Lider de Ventas | L7: Comercial | M7: 39470 | N7: =(CC$1-M7)/365 -> 18.2 | O7: 315 525 2674 | P7: MOTOCICLETA | Q7: A2 | R7: 45097 | S7: Vencida | T7: 0 | U7: 0 | AD7: Moto | AH7: NO APLICA | AI7: NO APLICA | AJ7: =IF(AK7>TODAY(),"Vigente","No Vigente") -> No Vigente | AK7: =(AL7+365) -> 365 | AM7: =IF(AN7>TODAY(),"Vigente","No Vigente") -> No Vigente | AN7: =(AO7+365) -> 365 | AQ7: 45097 | AR7: =IF(AQ7>TODAY(),"Vigente","No Vigente") -> No Vigente | BC7: Restricciones medico laboral para ejercer funciones en motocicleta | BD7: No ha enviado información.
A8: 5 | D8: 1112476996 | E8: Aguilar Yina Paola | F8: 33886 | G8: FEMENINO | H8: Bachiller academico | I8: =(CC$1-F8)/365 -> 33.49863 | J8: Soltera | K8: Auxiliar Operativo de Recaudo | L8: Financiero | M8: 43587 | N8: =(CC$1-M8)/365 -> 6.9205479 | O8: 316 256 6801 - 3115242212 | P8: MOTOCICLETA | Q8: A2 | R8: 47902 | S8: Vigente | T8: 0 | V8: GKG13F | W8: 9F2C1125XL5008593 | X8: ZS154FMI-38L104874 | Y8: 2020 | Z8: AKT | AA8: 124 | AC8: 43811 | AD8: Moto | AE8: SI | AH8: NO APLICA | AI8: NO APLICA | AJ8: =IF(AK8>TODAY(),"Vigente","No Vigente") -> No Vigente | AK8: 45820 | AL8: 45455 | AM8: =IF(AN8>TODAY(),"Vigente","No Vigente") -> No Vigente | AN8: 45784 | AO8: 45420 | AP8: A2 | AQ8: 47902 | AR8: =IF(AQ8>TODAY(),"Vigente","No Vigente") -> Vigente | AU8: No tiene multas. | BC8: Debe conducir con lentes | BD8: Se actualiza manualmente información.
A9: 6 | D9: 94521502 | E9: Aguirre Bedoya Ivan Dario | F9: 28706 | G9: MASCULINO | I9: =(CC$1-F9)/365 -> 47.690411 | K9: Mensajero - Comercial | L9: Comercial | M9: 44572 | N9: =(CC$1-M9)/365 -> 4.2219178 | O9: 315 412 7343 | P9: MOTOCICLETA | Q9: A2 | R9: 46926 | S9: Vigente | T9: 0 | U9: 0 | V9: JEP16G | W9: 9G5HAR023PVNH0372 | X9: HA11EPM9M03300 | Y9: 2023 | Z9: Hero | AA9: 98 | AC9: 44842 | AD9: Moto | AE9: Si | AH9: 0.5 | AI9: 1 | AJ9: =IF(AK9>TODAY(),"Vigente","No Vigente") -> No Vigente | AK9: 45879 | AL9: 45207 | AM9: Vigente | AN9: =(AO9+365) -> 45572 | AO9: 45207 | AP9: A2 | AQ9: 46926 | AR9: =IF(AQ9>TODAY(),"Vigente","No Vigente") -> Vigente | AU9: Actualmente no tiene multas | BC9: Licencia B1 (29/09/2023) | BD9: Retirado
A10: 7 | D10: 1007544618 | E10: Alvarado Diaz Sebastian | F10: 37128 | G10: MASCULINO | I10: =(CC$1-F10)/365 -> 24.616438 | K10: Entrenador Comercial | L10: Comercial | M10: 44702 | N10: =(CC$1-M10)/365 -> 3.8657534 | O10: 313 616 2352 | P10: MOTOCICLETA | Q10: A2 | R10: 44313 | S10: Vigente | T10: 0 | U10: 0 | V10: CLK30G | W10: 9FMJA2590PF002207 | X10: JA25E-4903374 | Y10: 2023 | Z10: Honda | AA10: 124 | AC10: 44624 | AD10: Moto | AE10: Si | AH10: 0.5 | AI10: 1 | AJ10: =IF(AK10>TODAY(),"Vigente","No Vigente") -> No Vigente | AK10: 45720 | AL10: 45355 | AM10: Vigente | AN10: 45719 | AO10: 45353 | AP10: A2 | AQ10: 47965 | AR10: =IF(AQ10>TODAY(),"Vigente","No Vigente") -> Vigente | AU10: Actualmente no tiene multas
